<?php

declare(strict_types=1);

namespace LaminasTest\Cache\Storage\Plugin;

use ArrayObject;
use Exception;
use Laminas\Cache;
use Laminas\Cache\Storage\ExceptionEvent;
use Laminas\Cache\Storage\Plugin\PluginOptions;
use Laminas\EventManager\Test\EventListenerIntrospectionTrait;
use LaminasTest\Cache\Storage\TestAsset\MockAdapter;

use function array_shift;

final class ExceptionHandlerTest extends AbstractCommonPluginTestCase
{
    use EventListenerIntrospectionTrait;

    private MockAdapter $adapter;

    private PluginOptions $options;

    protected function setUp(): void
    {
        $this->adapter = new MockAdapter();
        $this->options = new Cache\Storage\Plugin\PluginOptions();
        $this->plugin  = new Cache\Storage\Plugin\ExceptionHandler();
        $this->plugin->setOptions($this->options);

        parent::setUp();
    }

    public static function getCommonPluginNamesProvider(): array
    {
        return [
            'lowercase with underscore' => ['exception_handler'],
            'lowercase'                 => ['exceptionhandler'],
            'UpperCamelCase'            => ['ExceptionHandler'],
            'camelCase'                 => ['exceptionHandler'],
        ];
    }

    public function testAddPlugin(): void
    {
        $this->adapter->addPlugin($this->plugin);

        // check attached callbacks
        $expectedListeners = [
            'getItem.exception'         => 'onException',
            'getItems.exception'        => 'onException',
            'hasItem.exception'         => 'onException',
            'hasItems.exception'        => 'onException',
            'getMetadata.exception'     => 'onException',
            'getMetadatas.exception'    => 'onException',
            'setItem.exception'         => 'onException',
            'setItems.exception'        => 'onException',
            'addItem.exception'         => 'onException',
            'addItems.exception'        => 'onException',
            'replaceItem.exception'     => 'onException',
            'replaceItems.exception'    => 'onException',
            'touchItem.exception'       => 'onException',
            'touchItems.exception'      => 'onException',
            'removeItem.exception'      => 'onException',
            'removeItems.exception'     => 'onException',
            'checkAndSetItem.exception' => 'onException',
            'clearExpired.exception'    => 'onException',
        ];
        foreach ($expectedListeners as $eventName => $expectedCallbackMethod) {
            $listeners = $this->getArrayOfListenersForEvent($eventName, $this->adapter->getEventManager());

            // event should attached only once
            self::assertCount(1, $listeners);

            // check expected callback method
            $cb = array_shift($listeners);
            self::assertArrayHasKey(0, $cb);
            self::assertSame($this->plugin, $cb[0]);
            self::assertArrayHasKey(1, $cb);
            self::assertSame($expectedCallbackMethod, $cb[1]);
        }
    }

    public function testRemovePlugin(): void
    {
        $this->adapter->addPlugin($this->plugin);
        $this->adapter->removePlugin($this->plugin);

        // no events should be attached
        self::assertCount(0, $this->getEventsFromEventManager($this->adapter->getEventManager()));
    }

    public function testOnExceptionCallCallback(): void
    {
        $expectedException = new Exception();
        $callbackCalled    = false;

        $this->options->setExceptionCallback(
            static function ($exception) use ($expectedException, &$callbackCalled): void {
                $callbackCalled = $exception === $expectedException;
            }
        );

        // run onException
        $result = null;
        $event  = new ExceptionEvent('getItem.exception', $this->adapter, new ArrayObject([
            'key'     => 'key',
            'options' => [],
        ]), $result, $expectedException);
        $this->plugin->onException($event);

        self::assertTrue(
            $callbackCalled,
            "Expected callback wasn't called or the expected exception wasn't the first argument"
        );
    }

    public function testDontThrowException(): void
    {
        $this->options->setThrowExceptions(false);

        // run onException
        $result = 'test';
        $event  = new ExceptionEvent('getItem.exception', $this->adapter, new ArrayObject([
            'key'     => 'key',
            'options' => [],
        ]), $result, new Exception());
        $this->plugin->onException($event);

        self::assertFalse($event->getThrowException());
        self::assertSame('test', $event->getResult());
    }
}
